Workbook

Sheet Справочник
A1: Справочник: эксперты, альтернативы, критерии
A2: Названия меняются только здесь, остальные листы ссылаются на них формулами.
A3: Эксперты
A4: Э1 | B4: Петров Артем
A5: Э2 | B5: Попова Полина
A6: Э3 | B6: Пауликайте Елона
A9: Код | B9: Альтернатива (кратко) | C9: Описание
A10: A1 | B10: Бронь | C10: Бронирование переговорных и рабочих мест
A11: A2 | B11: Бюджет | C11: Совместный семейный бюджет
A12: A3 | B12: Запись | C12: Онлайн-запись к мастеру
A13: A4 | B13: Привычки | C13: Трекер привычек с челленджами
A16: Код | B16: Критерий | C16: Тип (+ польза / - затраты)
A17: K1 | B17: Востребованность | C17: +
A18: K2 | B18: Простота реализации MVP | C18: +
A19: K3 | B19: Пригодность для оценки и планирования | C19: +
A20: K4 | B20: Потенциал монетизации | C20: +
A21: K5 | B21: Интерес и экспертиза команды | C21: +

Sheet Эксперт1
A1: ="Попарные сравнения, эксперт 1: "&Справочник!$B$4 -> Попарные сравнения, эксперт 1: Петров Артем
A2: Заполнить желтые ячейки выше диагонали по шкале Саати 1-9. Если элемент строки хуже элемента столбца: =1/3, =1/5 и т.д.
A4: Критерии (относительно цели: выбор концепции)
B5: =Справочник!$B$17 -> Востребованность | C5: =Справочник!$B$18 -> Простота реализации MVP | D5: =Справочник!$B$19 -> Пригодность для оценки и планирования | E5: =Справочник!$B$20 -> Потенциал монетизации | F5: =Справочник!$B$21 -> Интерес и экспертиза команды | G5: Среднее геом. строки | H5: Вес w | I5: (A*w)i | J5: (A*w)i / wi
A6: =Справочник!$B$17 -> Востребованность | B6: 1 | C6: =1/2 -> 0.5 | D6: =1/3 -> 0.33333333 | E6: 2 | F6: 1 | G6: =IF(COUNT(B6:F6)<5,"",GEOMEAN(B6:F6)) -> 0.80274156 | H6: =IFERROR(G6/SUM($G$6:$G$10),"") -> 0.13521243 | I6: =IFERROR(B6*$H$6+C6*$H$7+D6*$H$8+E6*$H$9+F6*$H$10,"") -> 0.67757077 | J6: =IFERROR(I6/H6,"") -> 5.0111575
A7: =Справочник!$B$18 -> Простота реализации MVP | B7: =IF(C6="","",1/C6) -> 2 | C7: 1 | D7: =1/2 -> 0.5 | E7: 3 | F7: 2 | G7: =IF(COUNT(B7:F7)<5,"",GEOMEAN(B7:F7)) -> 1.4309691 | H7: =IFERROR(G7/SUM($G$6:$G$10),"") -> 0.24103001 | I7: =IFERROR(B7*$H$6+C7*$H$7+D7*$H$8+E7*$H$9+F7*$H$10,"") -> 1.2118261 | J7: =IFERROR(I7/H7,"") -> 5.027698
A8: =Справочник!$B$19 -> Пригодность для оценки и планирования | B8: =IF(D6="","",1/D6) -> 3 | C8: =IF(D7="","",1/D7) -> 2 | D8: 1 | E8: 5 | F8: 3 | G8: =IF(COUNT(B8:F8)<5,"",GEOMEAN(B8:F8)) -> 2.4595095 | H8: =IFERROR(G8/SUM($G$6:$G$10),"") -> 0.41427561 | I8: =IFERROR(B8*$H$6+C8*$H$7+D8*$H$8+E8*$H$9+F8*$H$10,"") -> 2.0789578 | J8: =IFERROR(I8/H8,"") -> 5.0182964
A9: =Справочник!$B$20 -> Потенциал монетизации | B9: =IF(E6="","",1/E6) -> 0.5 | C9: =IF(E7="","",1/E7) -> 0.33333333 | D9: =IF(E8="","",1/E8) -> 0.2 | E9: 1 | F9: =1/2 -> 0.5 | G9: =IF(COUNT(B9:F9)<5,"",GEOMEAN(B9:F9)) -> 0.4409301 | H9: =IFERROR(G9/SUM($G$6:$G$10),"") -> 0.07426952 | I9: =IFERROR(B9*$H$6+C9*$H$7+D9*$H$8+E9*$H$9+F9*$H$10,"") -> 0.37268041 | J9: =IFERROR(I9/H9,"") -> 5.0179456
A10: =Справочник!$B$21 -> Интерес и экспертиза команды | B10: =IF(F6="","",1/F6) -> 1 | C10: =IF(F7="","",1/F7) -> 0.5 | D10: =IF(F8="","",1/F8) -> 0.33333333 | E10: =IF(F9="","",1/F9) -> 2 | F10: 1 | G10: =IF(COUNT(B10:F10)<5,"",GEOMEAN(B10:F10)) -> 0.80274156 | H10: =IFERROR(G10/SUM($G$6:$G$10),"") -> 0.13521243 | I10: =IFERROR(B10*$H$6+C10*$H$7+D10*$H$8+E10*$H$9+F10*$H$10,"") -> 0.67757077 | J10: =IFERROR(I10/H10,"") -> 5.0111575
A11: lambda max | B11: =IF(COUNT(J6:J10)<5,"",AVERAGE(J6:J10)) -> 5.017251 | C11: CI | D11: =IFERROR((B11-5)/(5-1),"") -> 0.0043127427 | E11: CR (RI=1.12) | F11: =IFERROR(D11/1.12,"") -> 0.0038506632 | G11: =IF(F11="","заполните матрицу",IF(F11<=0.1,"согласовано","CR > 0,1: пересмотреть")) -> согласовано
A17: ="Альтернативы по критерию: "&Справочник!$B$17 -> Альтернативы по критерию: Востребованность
B18: =Справочник!$B$10 -> Бронь | C18: =Справочник!$B$11 -> Бюджет | D18: =Справочник!$B$12 -> Запись | E18: =Справочник!$B$13 -> Привычки | F18: Среднее геом. строки | G18: Вес w | H18: (A*w)i | I18: (A*w)i / wi
A19: =Справочник!$B$10 -> Бронь | B19: 1 | C19: =1/2 -> 0.5 | D19: =1/3 -> 0.33333333 | E19: 1 | F19: =IF(COUNT(B19:E19)<4,"",GEOMEAN(B19:E19)) -> 0.6389431 | G19: =IFERROR(F19/SUM($F$19:$F$22),"") -> 0.14114486 | H19: =IFERROR(B19*$G$19+C19*$G$20+D19*$G$21+E19*$G$22,"") -> 0.56530985 | I19: =IFERROR(H19/G19,"") -> 4.0051748
A20: =Справочник!$B$11 -> Бюджет | B20: =IF(C19="","",1/C19) -> 2 | C20: 1 | D20: =1/2 -> 0.5 | E20: 2 | F20: =IF(COUNT(B20:E20)<4,"",GEOMEAN(B20:E20)) -> 1.1892071 | G20: =IFERROR(F20/SUM($F$19:$F$22),"") -> 0.26270019 | H20: =IFERROR(B20*$G$19+C20*$G$20+D20*$G$21+E20*$G$22,"") -> 1.0547847 | I20: =IFERROR(H20/G20,"") -> 4.0151653
A21: =Справочник!$B$12 -> Запись | B21: =IF(D19="","",1/D19) -> 3 | C21: =IF(D20="","",1/D20) -> 2 | D21: 1 | E21: 3 | F21: =IF(COUNT(B21:E21)<4,"",GEOMEAN(B21:E21)) -> 2.0597671 | G21: =IFERROR(F21/SUM($F$19:$F$22),"") -> 0.45501008 | H21: =IFERROR(B21*$G$19+C21*$G$20+D21*$G$21+E21*$G$22,"") -> 1.8272796 | I21: =IFERROR(H21/G21,"") -> 4.0159103
A22: =Справочник!$B$13 -> Привычки | B22: =IF(E19="","",1/E19) -> 1 | C22: =IF(E20="","",1/E20) -> 0.5 | D22: =IF(E21="","",1/E21) -> 0.33333333 | E22: 1 | F22: =IF(COUNT(B22:E22)<4,"",GEOMEAN(B22:E22)) -> 0.6389431 | G22: =IFERROR(F22/SUM($F$19:$F$22),"") -> 0.14114486 | H22: =IFERROR(B22*$G$19+C22*$G$20+D22*$G$21+E22*$G$22,"") -> 0.56530985 | I22: =IFERROR(H22/G22,"") -> 4.0051748
A23: lambda max | B23: =IF(COUNT(I19:I22)<4,"",AVERAGE(I19:I22)) -> 4.0103563 | C23: CI | D23: =IFERROR((B23-4)/(4-1),"") -> 0.0034520922 | E23: CR (RI=0.9) | F23: =IFERROR(D23/0.9,"") -> 0.003835658 | G23: =IF(F23="","заполните матрицу",IF(F23<=0.1,"согласовано","CR > 0,1: пересмотреть")) -> согласовано
A30: ="Альтернативы по критерию: "&Справочник!$B$18 -> Альтернативы по критерию: Простота реализации MVP
B31: =Справочник!$B$10 -> Бронь | C31: =Справочник!$B$11 -> Бюджет | D31: =Справочник!$B$12 -> Запись | E31: =Справочник!$B$13 -> Привычки | F31: Среднее геом. строки | G31: Вес w | H31: (A*w)i | I31: (A*w)i / wi
A32: =Справочник!$B$10 -> Бронь | B32: 1 | C32: 2 | D32: 2 | E32: =1/2 -> 0.5 | F32: =IF(COUNT(B32:E32)<4,"",GEOMEAN(B32:E32)) -> 1.1892071 | G32: =IFERROR(F32/SUM($F$32:$F$35),"") -> 0.26270019 | H32: =IFERROR(B32*$G$32+C32*$G$33+D32*$G$34+E32*$G$35,"") -> 1.0547847 | I32: =IFERROR(H32/G32,"") -> 4.0151653
A33: =Справочник!$B$11 -> Бюджет | B33: =IF(C32="","",1/C32) -> 0.5 | C33: 1 | D33: 1 | E33: =1/3 -> 0.33333333 | F33: =IF(COUNT(B33:E33)<4,"",GEOMEAN(B33:E33)) -> 0.6389431 | G33: =IFERROR(F33/SUM($F$32:$F$35),"") -> 0.14114486 | H33: =IFERROR(B33*$G$32+C33*$G$33+D33*$G$34+E33*$G$35,"") -> 0.56530985 | I33: =IFERROR(H33/G33,"") -> 4.0051748
A34: =Справочник!$B$12 -> Запись | B34: =IF(D32="","",1/D32) -> 0.5 | C34: =IF(D33="","",1/D33) -> 1 | D34: 1 | E34: =1/3 -> 0.33333333 | F34: =IF(COUNT(B34:E34)<4,"",GEOMEAN(B34:E34)) -> 0.6389431 | G34: =IFERROR(F34/SUM($F$32:$F$35),"") -> 0.14114486 | H34: =IFERROR(B34*$G$32+C34*$G$33+D34*$G$34+E34*$G$35,"") -> 0.56530985 | I34: =IFERROR(H34/G34,"") -> 4.0051748
A35: =Справочник!$B$13 -> Привычки | B35: =IF(E32="","",1/E32) -> 2 | C35: =IF(E33="","",1/E33) -> 3 | D35: =IF(E34="","",1/E34) -> 3 | E35: 1 | F35: =IF(COUNT(B35:E35)<4,"",GEOMEAN(B35:E35)) -> 2.0597671 | G35: =IFERROR(F35/SUM($F$32:$F$35),"") -> 0.45501008 | H35: =IFERROR(B35*$G$32+C35*$G$33+D35*$G$34+E35*$G$35,"") -> 1.8272796 | I35: =IFERROR(H35/G35,"") -> 4.0159103
A36: lambda max | B36: =IF(COUNT(I32:I35)<4,"",AVERAGE(I32:I35)) -> 4.0103563 | C36: CI | D36: =IFERROR((B36-4)/(4-1),"") -> 0.0034520922 | E36: CR (RI=0.9) | F36: =IFERROR(D36/0.9,"") -> 0.003835658 | G36: =IF(F36="","заполните матрицу",IF(F36<=0.1,"согласовано","CR > 0,1: пересмотреть")) -> согласовано
A43: ="Альтернативы по критерию: "&Справочник!$B$19 -> Альтернативы по критерию: Пригодность для оценки и планирования
B44: =Справочник!$B$10 -> Бронь | C44: =Справочник!$B$11 -> Бюджет | D44: =Справочник!$B$12 -> Запись | E44: =Справочник!$B$13 -> Привычки | F44: Среднее геом. строки | G44: Вес w | H44: (A*w)i | I44: (A*w)i / wi
A45: =Справочник!$B$10 -> Бронь | B45: 1 | C45: 3 | D45: =1/2 -> 0.5 | E45: 3 | F45: =IF(COUNT(B45:E45)<4,"",GEOMEAN(B45:E45)) -> 1.4564753 | G45: =IFERROR(F45/SUM($F$45:$F$48),"") -> 0.29666714 | H45: =IFERROR(B45*$G$45+C45*$G$46+D45*$G$47+E45*$G$48,"") -> 1.1955272 | I45: =IFERROR(H45/G45,"") -> 4.0298604
A46: =Справочник!$B$11 -> Бюджет | B46: =IF(C45="","",1/C45) -> 0.33333333 | C46: 1 | D46: =1/4 -> 0.25 | E46: 1 | F46: =IF(COUNT(B46:E46)<4,"",GEOMEAN(B46:E46)) -> 0.53728497 | G46: =IFERROR(F46/SUM($F$45:$F$48),"") -> 0.10943872 | H46: =IFERROR(B46*$G$45+C46*$G$46+D46*$G$47+E46*$G$48,"") -> 0.43888034 | I46: =IFERROR(H46/G46,"") -> 4.0102839
A47: =Справочник!$B$12 -> Запись | B47: =IF(D45="","",1/D45) -> 2 | C47: =IF(D46="","",1/D46) -> 4 | D47: 1 | E47: 4 | F47: =IF(COUNT(B47:E47)<4,"",GEOMEAN(B47:E47)) -> 2.3784142 | G47: =IFERROR(F47/SUM($F$45:$F$48),"") -> 0.48445542 | H47: =IFERROR(B47*$G$45+C47*$G$46+D47*$G$47+E47*$G$48,"") -> 1.9532995 | I47: =IFERROR(H47/G47,"") -> 4.0319489
A48: =Справочник!$B$13 -> Привычки | B48: =IF(E45="","",1/E45) -> 0.33333333 | C48: =IF(E46="","",1/E46) -> 1 | D48: =IF(E47="","",1/E47) -> 0.25 | E48: 1 | F48: =IF(COUNT(B48:E48)<4,"",GEOMEAN(B48:E48)) -> 0.53728497 | G48: =IFERROR(F48/SUM($F$45:$F$48),"") -> 0.10943872 | H48: =IFERROR(B48*$G$45+C48*$G$46+D48*$G$47+E48*$G$48,"") -> 0.43888034 | I48: =IFERROR(H48/G48,"") -> 4.0102839
A49: lambda max | B49: =IF(COUNT(I45:I48)<4,"",AVERAGE(I45:I48)) -> 4.0205943 | C49: CI | D49: =IFERROR((B49-4)/(4-1),"") -> 0.0068647621 | E49: CR (RI=0.9) | F49: =IFERROR(D49/0.9,"") -> 0.0076275135 | G49: =IF(F49="","заполните матрицу",IF(F49<=0.1,"согласовано","CR > 0,1: пересмотреть")) -> согласовано
A56: ="Альтернативы по критерию: "&Справочник!$B$20 -> Альтернативы по критерию: Потенциал монетизации
B57: =Справочник!$B$10 -> Бронь | C57: =Справочник!$B$11 -> Бюджет | D57: =Справочник!$B$12 -> Запись | E57: =Справочник!$B$13 -> Привычки | F57: Среднее геом. строки | G57: Вес w | H57: (A*w)i | I57: (A*w)i / wi
A58: =Справочник!$B$10 -> Бронь | B58: 1 | C58: 1 | D58: =1/4 -> 0.25 | E58: 2 | F58: =IF(COUNT(B58:E58)<4,"",GEOMEAN(B58:E58)) -> 0.84089642 | G58: =IFERROR(F58/SUM($F$58:$F$61),"") -> 0.16342806 | H58: =IFERROR(B58*$G$58+C58*$G$59+D58*$G$60+E58*$G$61,"") -> 0.65597121 | I58: =IFERROR(H58/G58,"") -> 4.0138224
A59: =Справочник!$B$11 -> Бюджет | B59: =IF(C58="","",1/C58) -> 1 | C59: 1 | D59: =1/4 -> 0.25 | E59: 2 | F59: =IF(COUNT(B59:E59)<4,"",GEOMEAN(B59:E59)) -> 0.84089642 | G59: =IFERROR(F59/SUM($F$58:$F$61),"") -> 0.16342806 | H59: =IFERROR(B59*$G$58+C59*$G$59+D59*$G$60+E59*$G$61,"") -> 0.65597121 | I59: =IFERROR(H59/G59,"") -> 4.0138224
A60: =Справочник!$B$12 -> Запись | B60: =IF(D58="","",1/D58) -> 4 | C60: =IF(D59="","",1/D59) -> 4 | D60: 1 | E60: 5 | F60: =IF(COUNT(B60:E60)<4,"",GEOMEAN(B60:E60)) -> 2.9906976 | G60: =IFERROR(F60/SUM($F$58:$F$61),"") -> 0.58124152 | H60: =IFERROR(B60*$G$58+C60*$G$59+D60*$G$60+E60*$G$61,"") -> 2.3481778 | I60: =IFERROR(H60/G60,"") -> 4.0399347
A61: =Справочник!$B$13 -> Привычки | B61: =IF(E58="","",1/E58) -> 0.5 | C61: =IF(E59="","",1/E59) -> 0.5 | D61: =IF(E60="","",1/E60) -> 0.2 | E61: 1 | F61: =IF(COUNT(B61:E61)<4,"",GEOMEAN(B61:E61)) -> 0.4728708 | G61: =IFERROR(F61/SUM($F$58:$F$61),"") -> 0.091902354 | H61: =IFERROR(B61*$G$58+C61*$G$59+D61*$G$60+E61*$G$61,"") -> 0.37157872 | I61: =IFERROR(H61/G61,"") -> 4.0431905
A62: lambda max | B62: =IF(COUNT(I58:I61)<4,"",AVERAGE(I58:I61)) -> 4.0276925 | C62: CI | D62: =IFERROR((B62-4)/(4-1),"") -> 0.0092308251 | E62: CR (RI=0.9) | F62: =IFERROR(D62/0.9,"") -> 0.010256472 | G62: =IF(F62="","заполните матрицу",IF(F62<=0.1,"согласовано","CR > 0,1: пересмотреть")) -> согласовано
A69: ="Альтернативы по критерию: "&Справочник!$B$21 -> Альтернативы по критерию: Интерес и экспертиза команды
B70: =Справочник!$B$10 -> Бронь | C70: =Справочник!$B$11 -> Бюджет | D70: =Справочник!$B$12 -> Запись | E70: =Справочник!$B$13 -> Привычки | F70: Среднее геом. строки | G70: Вес w | H70: (A*w)i | I70: (A*w)i / wi
...

Sheet Эксперт2
A1: ="Попарные сравнения, эксперт 2: "&Справочник!$B$5 -> Попарные сравнения, эксперт 2: Попова Полина
A2: Заполнить желтые ячейки выше диагонали по шкале Саати 1-9. Если элемент строки хуже элемента столбца: =1/3, =1/5 и т.д.
A4: Критерии (относительно цели: выбор концепции)
B5: =Справочник!$B$17 -> Востребованность | C5: =Справочник!$B$18 -> Простота реализации MVP | D5: =Справочник!$B$19 -> Пригодность для оценки и планирования | E5: =Справочник!$B$20 -> Потенциал монетизации | F5: =Справочник!$B$21 -> Интерес и экспертиза команды | G5: Среднее геом. строки | H5: Вес w | I5: (A*w)i | J5: (A*w)i / wi
A6: =Справочник!$B$17 -> Востребованность | B6: 1 | C6: 0.5 | D6: 0.45 | E6: 2 | F6: 1 | G6: =IF(COUNT(B6:F6)<5,"",GEOMEAN(B6:F6)) -> 0.85239816 | H6: =IFERROR(G6/SUM($G$6:$G$10),"") -> 0.15269564 | I6: =IFERROR(B6*$H$6+C6*$H$7+D6*$H$8+E6*$H$9+F6*$H$10,"") -> 0.77942812 | J6: =IFERROR(I6/H6,"") -> 5.1044556
A7: =Справочник!$B$18 -> Простота реализации MVP | B7: =IF(C6="","",1/C6) -> 2 | C7: 1 | D7: 0.4 | E7: 2 | F7: 2 | G7: =IF(COUNT(B7:F7)<5,"",GEOMEAN(B7:F7)) -> 1.2619147 | H7: =IFERROR(G7/SUM($G$6:$G$10),"") -> 0.22605501 | I7: =IFERROR(B7*$H$6+C7*$H$7+D7*$H$8+E7*$H$9+F7*$H$10,"") -> 1.1617812 | J7: =IFERROR(I7/H7,"") -> 5.1393741
A8: =Справочник!$B$19 -> Пригодность для оценки и планирования | B8: =IF(D6="","",1/D6) -> 2.2222222 | C8: =IF(D7="","",1/D7) -> 2.5 | D8: 1 | E8: 4 | F8: 2 | G8: =IF(COUNT(B8:F8)<5,"",GEOMEAN(B8:F8)) -> 2.1358143 | H8: =IFERROR(G8/SUM($G$6:$G$10),"") -> 0.38260235 | I8: =IFERROR(B8*$H$6+C8*$H$7+D8*$H$8+E8*$H$9+F8*$H$10,"") -> 1.9701313 | J8: =IFERROR(I8/H8,"") -> 5.1492924
A9: =Справочник!$B$20 -> Потенциал монетизации | B9: =IF(E6="","",1/E6) -> 0.5 | C9: =IF(E7="","",1/E7) -> 0.5 | D9: =IF(E8="","",1/E8) -> 0.25 | E9: 1 | F9: 1 | G9: =IF(COUNT(B9:F9)<5,"",GEOMEAN(B9:F9)) -> 0.57434918 | H9: =IFERROR(G9/SUM($G$6:$G$10),"") -> 0.10288691 | I9: =IFERROR(B9*$H$6+C9*$H$7+D9*$H$8+E9*$H$9+F9*$H$10,"") -> 0.52367292 | J9: =IFERROR(I9/H9,"") -> 5.0897913
A10: =Справочник!$B$21 -> Интерес и экспертиза команды | B10: =IF(F6="","",1/F6) -> 1 | C10: =IF(F7="","",1/F7) -> 0.5 | D10: =IF(F8="","",1/F8) -> 0.5 | E10: =IF(F9="","",1/F9) -> 1 | F10: 1 | G10: =IF(COUNT(B10:F10)<5,"",GEOMEAN(B10:F10)) -> 0.75785828 | H10: =IFERROR(G10/SUM($G$6:$G$10),"") -> 0.1357601 | I10: =IFERROR(B10*$H$6+C10*$H$7+D10*$H$8+E10*$H$9+F10*$H$10,"") -> 0.69567132 | J10: =IFERROR(I10/H10,"") -> 5.1242696
A11: lambda max | B11: =IF(COUNT(J6:J10)<5,"",AVERAGE(J6:J10)) -> 5.1214366 | C11: CI | D11: =IFERROR((B11-5)/(5-1),"") -> 0.03035915 | E11: CR (RI=1.12) | F11: =IFERROR(D11/1.12,"") -> 0.027106384 | G11: =IF(F11="","заполните матрицу",IF(F11<=0.1,"согласовано","CR > 0,1: пересмотреть")) -> согласовано
A17: ="Альтернативы по критерию: "&Справочник!$B$17 -> Альтернативы по критерию: Востребованность
B18: =Справочник!$B$10 -> Бронь | C18: =Справочник!$B$11 -> Бюджет | D18: =Справочник!$B$12 -> Запись | E18: =Справочник!$B$13 -> Привычки | F18: Среднее геом. строки | G18: Вес w | H18: (A*w)i | I18: (A*w)i / wi
A19: =Справочник!$B$10 -> Бронь | B19: 1 | C19: 1 | D19: 0.3 | E19: 1 | F19: =IF(COUNT(B19:E19)<4,"",GEOMEAN(B19:E19)) -> 0.7400828 | G19: =IFERROR(F19/SUM($F$19:$F$22),"") -> 0.17081089 | H19: =IFERROR(B19*$G$19+C19*$G$20+D19*$G$21+E19*$G$22,"") -> 0.69127772 | I19: =IFERROR(H19/G19,"") -> 4.0470354
A20: =Справочник!$B$11 -> Бюджет | B20: =IF(C19="","",1/C19) -> 1 | C20: 1 | D20: 0.5 | E20: 1 | F20: =IF(COUNT(B20:E20)<4,"",GEOMEAN(B20:E20)) -> 0.84089642 | G20: =IFERROR(F20/SUM($F$19:$F$22),"") -> 0.19407864 | H20: =IFERROR(B20*$G$19+C20*$G$20+D20*$G$21+E20*$G$22,"") -> 0.77948409 | I20: =IFERROR(H20/G20,"") -> 4.0163311
A21: =Справочник!$B$12 -> Запись | B21: =IF(D19="","",1/D19) -> 3.3333333 | C21: =IF(D20="","",1/D20) -> 2 | D21: 1 | E21: 2 | F21: =IF(COUNT(B21:E21)<4,"",GEOMEAN(B21:E21)) -> 1.9108856 | G21: =IFERROR(F21/SUM($F$19:$F$22),"") -> 0.44103182 | H21: =IFERROR(B21*$G$19+C21*$G$20+D21*$G$21+E21*$G$22,"") -> 1.786716 | I21: =IFERROR(H21/G21,"") -> 4.0512179
A22: =Справочник!$B$13 -> Привычки | B22: =IF(E19="","",1/E19) -> 1 | C22: =IF(E20="","",1/E20) -> 1 | D22: =IF(E21="","",1/E21) -> 0.5 | E22: 1 | F22: =IF(COUNT(B22:E22)<4,"",GEOMEAN(B22:E22)) -> 0.84089642 | G22: =IFERROR(F22/SUM($F$19:$F$22),"") -> 0.19407864 | H22: =IFERROR(B22*$G$19+C22*$G$20+D22*$G$21+E22*$G$22,"") -> 0.77948409 | I22: =IFERROR(H22/G22,"") -> 4.0163311
A23: lambda max | B23: =IF(COUNT(I19:I22)<4,"",AVERAGE(I19:I22)) -> 4.0327289 | C23: CI | D23: =IFERROR((B23-4)/(4-1),"") -> 0.010909628 | E23: CR (RI=0.9) | F23: =IFERROR(D23/0.9,"") -> 0.012121808 | G23: =IF(F23="","заполните матрицу",IF(F23<=0.1,"согласовано","CR > 0,1: пересмотреть")) -> согласовано
A30: ="Альтернативы по критерию: "&Справочник!$B$18 -> Альтернативы по критерию: Простота реализации MVP
B31: =Справочник!$B$10 -> Бронь | C31: =Справочник!$B$11 -> Бюджет | D31: =Справочник!$B$12 -> Запись | E31: =Справочник!$B$13 -> Привычки | F31: Среднее геом. строки | G31: Вес w | H31: (A*w)i | I31: (A*w)i / wi
A32: =Справочник!$B$10 -> Бронь | B32: 1 | C32: 3 | D32: 2 | E32: 1 | F32: =IF(COUNT(B32:E32)<4,"",GEOMEAN(B32:E32)) -> 1.5650846 | G32: =IFERROR(F32/SUM($F$32:$F$35),"") -> 0.34446193 | H32: =IFERROR(B32*$G$32+C32*$G$33+D32*$G$34+E32*$G$35,"") -> 1.5368507 | I32: =IFERROR(H32/G32,"") -> 4.4615982
A33: =Справочник!$B$11 -> Бюджет | B33: =IF(C32="","",1/C32) -> 0.33333333 | C33: 1 | D33: 0.3 | E33: 0.3 | F33: =IF(COUNT(B33:E33)<4,"",GEOMEAN(B33:E33)) -> 0.41617915 | G33: =IFERROR(F33/SUM($F$32:$F$35),"") -> 0.091597522 | H33: =IFERROR(B33*$G$32+C33*$G$33+D33*$G$34+E33*$G$35,"") -> 0.37560033 | I33: =IFERROR(H33/G33,"") -> 4.1005512
A34: =Справочник!$B$12 -> Запись | B34: =IF(D32="","",1/D32) -> 0.5 | C34: =IF(D33="","",1/D33) -> 3.3333333 | D34: 1 | E34: 4 | F34: =IF(COUNT(B34:E34)<4,"",GEOMEAN(B34:E34)) -> 1.6068568 | G34: =IFERROR(F34/SUM($F$32:$F$35),"") -> 0.35365565 | H34: =IFERROR(B34*$G$32+C34*$G$33+D34*$G$34+E34*$G$35,"") -> 1.6723513 | I34: =IFERROR(H34/G34,"") -> 4.7287561
A35: =Справочник!$B$13 -> Привычки | B35: =IF(E32="","",1/E32) -> 1 | C35: =IF(E33="","",1/E33) -> 3.3333333 | D35: =IF(E34="","",1/E34) -> 0.25 | E35: 1 | F35: =IF(COUNT(B35:E35)<4,"",GEOMEAN(B35:E35)) -> 0.95544279 | G35: =IFERROR(F35/SUM($F$32:$F$35),"") -> 0.21028491 | H35: =IFERROR(B35*$G$32+C35*$G$33+D35*$G$34+E35*$G$35,"") -> 0.94848582 | I35: =IFERROR(H35/G35,"") -> 4.5104798
A36: lambda max | B36: =IF(COUNT(I32:I35)<4,"",AVERAGE(I32:I35)) -> 4.4503463 | C36: CI | D36: =IFERROR((B36-4)/(4-1),"") -> 0.15011544 | E36: CR (RI=0.9) | F36: =IFERROR(D36/0.9,"") -> 0.16679493 | G36: =IF(F36="","заполните матрицу",IF(F36<=0.1,"согласовано","CR > 0,1: пересмотреть")) -> CR > 0,1: пересмотреть
A43: ="Альтернативы по критерию: "&Справочник!$B$19 -> Альтернативы по критерию: Пригодность для оценки и планирования
B44: =Справочник!$B$10 -> Бронь | C44: =Справочник!$B$11 -> Бюджет | D44: =Справочник!$B$12 -> Запись | E44: =Справочник!$B$13 -> Привычки | F44: Среднее геом. строки | G44: Вес w | H44: (A*w)i | I44: (A*w)i / wi
A45: =Справочник!$B$10 -> Бронь | B45: 1 | C45: 3 | D45: 0.5 | E45: 3 | F45: =IF(COUNT(B45:E45)<4,"",GEOMEAN(B45:E45)) -> 1.4564753 | G45: =IFERROR(F45/SUM($F$45:$F$48),"") -> 0.29032191 | H45: =IFERROR(B45*$G$45+C45*$G$46+D45*$G$47+E45*$G$48,"") -> 1.1661236 | I45: =IFERROR(H45/G45,"") -> 4.0166571
A46: =Справочник!$B$11 -> Бюджет | B46: =IF(C45="","",1/C45) -> 0.33333333 | C46: 1 | D46: 0.2 | E46: 1 | F46: =IF(COUNT(B46:E46)<4,"",GEOMEAN(B46:E46)) -> 0.50813275 | G46: =IFERROR(F46/SUM($F$45:$F$48),"") -> 0.10128704 | H46: =IFERROR(B46*$G$45+C46*$G$46+D46*$G$47+E46*$G$48,"") -> 0.40541762 | I46: =IFERROR(H46/G46,"") -> 4.0026605
A47: =Справочник!$B$12 -> Запись | B47: =IF(D45="","",1/D45) -> 2 | C47: =IF(D46="","",1/D46) -> 5 | D47: 1 | E47: 4 | F47: =IF(COUNT(B47:E47)<4,"",GEOMEAN(B47:E47)) -> 2.5148669 | G47: =IFERROR(F47/SUM($F$45:$F$48),"") -> 0.50129305 | H47: =IFERROR(B47*$G$45+C47*$G$46+D47*$G$47+E47*$G$48,"") -> 2.0167641 | I47: =IFERROR(H47/G47,"") -> 4.023124
A48: =Справочник!$B$13 -> Привычки | B48: =IF(E45="","",1/E45) -> 0.33333333 | C48: =IF(E46="","",1/E46) -> 1 | D48: =IF(E47="","",1/E47) -> 0.25 | E48: 1 | F48: =IF(COUNT(B48:E48)<4,"",GEOMEAN(B48:E48)) -> 0.53728497 | G48: =IFERROR(F48/SUM($F$45:$F$48),"") -> 0.107098 | H48: =IFERROR(B48*$G$45+C48*$G$46+D48*$G$47+E48*$G$48,"") -> 0.43048227 | I48: =IFERROR(H48/G48,"") -> 4.0195173
A49: lambda max | B49: =IF(COUNT(I45:I48)<4,"",AVERAGE(I45:I48)) -> 4.0154897 | C49: CI | D49: =IFERROR((B49-4)/(4-1),"") -> 0.00516323 | E49: CR (RI=0.9) | F49: =IFERROR(D49/0.9,"") -> 0.0057369222 | G49: =IF(F49="","заполните матрицу",IF(F49<=0.1,"согласовано","CR > 0,1: пересмотреть")) -> согласовано
A56: ="Альтернативы по критерию: "&Справочник!$B$20 -> Альтернативы по критерию: Потенциал монетизации
B57: =Справочник!$B$10 -> Бронь | C57: =Справочник!$B$11 -> Бюджет | D57: =Справочник!$B$12 -> Запись | E57: =Справочник!$B$13 -> Привычки | F57: Среднее геом. строки | G57: Вес w | H57: (A*w)i | I57: (A*w)i / wi
A58: =Справочник!$B$10 -> Бронь | B58: 1 | C58: 1 | D58: 0.25 | E58: 2 | F58: =IF(COUNT(B58:E58)<4,"",GEOMEAN(B58:E58)) -> 0.84089642 | G58: =IFERROR(F58/SUM($F$58:$F$61),"") -> 0.17238609 | H58: =IFERROR(B58*$G$58+C58*$G$59+D58*$G$60+E58*$G$61,"") -> 0.70639573 | I58: =IFERROR(H58/G58,"") -> 4.0977537
A59: =Справочник!$B$11 -> Бюджет | B59: =IF(C58="","",1/C58) -> 1 | C59: 1 | D59: 0.3 | E59: 1 | F59: =IF(COUNT(B59:E59)<4,"",GEOMEAN(B59:E59)) -> 0.7400828 | G59: =IFERROR(F59/SUM($F$58:$F$61),"") -> 0.15171902 | H59: =IFERROR(B59*$G$58+C59*$G$59+D59*$G$60+E59*$G$61,"") -> 0.61220033 | I59: =IFERROR(H59/G59,"") -> 4.0350929
A60: =Справочник!$B$12 -> Запись | B60: =IF(D58="","",1/D58) -> 4 | C60: =IF(D59="","",1/D59) -> 3.3333333 | D60: 1 | E60: 4 | F60: =IF(COUNT(B60:E60)<4,"",GEOMEAN(B60:E60)) -> 2.7024003 | G60: =IFERROR(F60/SUM($F$58:$F$61),"") -> 0.55399952 | H60: =IFERROR(B60*$G$58+C60*$G$59+D60*$G$60+E60*$G$61,"") -> 2.2368554 | I60: =IFERROR(H60/G60,"") -> 4.0376486
A61: =Справочник!$B$13 -> Привычки | B61: =IF(E58="","",1/E58) -> 0.5 | C61: =IF(E59="","",1/E59) -> 1 | D61: =IF(E60="","",1/E60) -> 0.25 | E61: 1 | F61: =IF(COUNT(B61:E61)<4,"",GEOMEAN(B61:E61)) -> 0.59460356 | G61: =IFERROR(F61/SUM($F$58:$F$61),"") -> 0.12189537 | H61: =IFERROR(B61*$G$58+C61*$G$59+D61*$G$60+E61*$G$61,"") -> 0.49830731 | I61: =IFERROR(H61/G61,"") -> 4.0879921
A62: lambda max | B62: =IF(COUNT(I58:I61)<4,"",AVERAGE(I58:I61)) -> 4.0646218 | C62: CI | D62: =IFERROR((B62-4)/(4-1),"") -> 0.021540612 | E62: CR (RI=0.9) | F62: =IFERROR(D62/0.9,"") -> 0.023934013 | G62: =IF(F62="","заполните матрицу",IF(F62<=0.1,"согласовано","CR > 0,1: пересмотреть")) -> согласовано
A69: ="Альтернативы по критерию: "&Справочник!$B$21 -> Альтернативы по критерию: Интерес и экспертиза команды
B70: =Справочник!$B$10 -> Бронь | C70: =Справочник!$B$11 -> Бюджет | D70: =Справочник!$B$12 -> Запись | E70: =Справочник!$B$13 -> Привычки | F70: Среднее геом. строки | G70: Вес w | H70: (A*w)i | I70: (A*w)i / wi
...

Sheet Эксперт3
A1: ="Попарные сравнения, эксперт 3: "&Справочник!$B$6 -> Попарные сравнения, эксперт 3: Пауликайте Елона
A2: Заполнить желтые ячейки выше диагонали по шкале Саати 1-9. Если элемент строки хуже элемента столбца: =1/3, =1/5 и т.д.
A4: Критерии (относительно цели: выбор концепции)
B5: =Справочник!$B$17 -> Востребованность | C5: =Справочник!$B$18 -> Простота реализации MVP | D5: =Справочник!$B$19 -> Пригодность для оценки и планирования | E5: =Справочник!$B$20 -> Потенциал монетизации | F5: =Справочник!$B$21 -> Интерес и экспертиза команды | G5: Среднее геом. строки | H5: Вес w | I5: (A*w)i | J5: (A*w)i / wi
A6: =Справочник!$B$17 -> Востребованность | B6: 1 | C6: 0.5 | D6: 0.33333333 | E6: 2 | F6: 1 | G6: =IF(COUNT(B6:F6)<5,"",GEOMEAN(B6:F6)) -> 0.80274156 | H6: =IFERROR(G6/SUM($G$6:$G$10),"") -> 0.13910427 | I6: =IFERROR(B6*$H$6+C6*$H$7+D6*$H$8+E6*$H$9+F6*$H$10,"") -> 0.69932074 | J6: =IFERROR(I6/H6,"") -> 5.0273131
A7: =Справочник!$B$18 -> Простота реализации MVP | B7: =IF(C6="","",1/C6) -> 2 | C7: 1 | D7: 0.4 | E7: 3 | F7: 2 | G7: =IF(COUNT(B7:F7)<5,"",GEOMEAN(B7:F7)) -> 1.3685109 | H7: =IFERROR(G7/SUM($G$6:$G$10),"") -> 0.23714445 | I7: =IFERROR(B7*$H$6+C7*$H$7+D7*$H$8+E7*$H$9+F7*$H$10,"") -> 1.2139465 | J7: =IFERROR(I7/H7,"") -> 5.1190169
A8: =Справочник!$B$19 -> Пригодность для оценки и планирования | B8: =IF(D6="","",1/D6) -> 3 | C8: =IF(D7="","",1/D7) -> 2.5 | D8: 1 | E8: 4 | F8: 2 | G8: =IF(COUNT(B8:F8)<5,"",GEOMEAN(B8:F8)) -> 2.2679332 | H8: =IFERROR(G8/SUM($G$6:$G$10),"") -> 0.39300219 | I8: =IFERROR(B8*$H$6+C8*$H$7+D8*$H$8+E8*$H$9+F8*$H$10,"") -> 2.0244632 | J8: =IFERROR(I8/H8,"") -> 5.151277
A9: =Справочник!$B$20 -> Потенциал монетизации | B9: =IF(E6="","",1/E6) -> 0.5 | C9: =IF(E7="","",1/E7) -> 0.33333333 | D9: =IF(E8="","",1/E8) -> 0.25 | E9: 1 | F9: 0.5 | G9: =IF(COUNT(B9:F9)<5,"",GEOMEAN(B9:F9)) -> 0.46105396 | H9: =IFERROR(G9/SUM($G$6:$G$10),"") -> 0.079894425 | I9: =IFERROR(B9*$H$6+C9*$H$7+D9*$H$8+E9*$H$9+F9*$H$10,"") -> 0.40217259 | J9: =IFERROR(I9/H9,"") -> 5.0338004
A10: =Справочник!$B$21 -> Интерес и экспертиза команды | B10: =IF(F6="","",1/F6) -> 1 | C10: =IF(F7="","",1/F7) -> 0.5 | D10: =IF(F8="","",1/F8) -> 0.5 | E10: =IF(F9="","",1/F9) -> 2 | F10: 1 | G10: =IF(COUNT(B10:F10)<5,"",GEOMEAN(B10:F10)) -> 0.87055056 | H10: =IFERROR(G10/SUM($G$6:$G$10),"") -> 0.15085466 | I10: =IFERROR(B10*$H$6+C10*$H$7+D10*$H$8+E10*$H$9+F10*$H$10,"") -> 0.7648211 | J10: =IFERROR(I10/H10,"") -> 5.0699204
A11: lambda max | B11: =IF(COUNT(J6:J10)<5,"",AVERAGE(J6:J10)) -> 5.0802656 | C11: CI | D11: =IFERROR((B11-5)/(5-1),"") -> 0.020066392 | E11: CR (RI=1.12) | F11: =IFERROR(D11/1.12,"") -> 0.017916422 | G11: =IF(F11="","заполните матрицу",IF(F11<=0.1,"согласовано","CR > 0,1: пересмотреть")) -> согласовано
A17: ="Альтернативы по критерию: "&Справочник!$B$17 -> Альтернативы по критерию: Востребованность
B18: =Справочник!$B$10 -> Бронь | C18: =Справочник!$B$11 -> Бюджет | D18: =Справочник!$B$12 -> Запись | E18: =Справочник!$B$13 -> Привычки | F18: Среднее геом. строки | G18: Вес w | H18: (A*w)i | I18: (A*w)i / wi
A19: =Справочник!$B$10 -> Бронь | B19: 1 | C19: 1 | D19: 0.3 | E19: 1 | F19: =IF(COUNT(B19:E19)<4,"",GEOMEAN(B19:E19)) -> 0.7400828 | G19: =IFERROR(F19/SUM($F$19:$F$22),"") -> 0.16981873 | H19: =IFERROR(B19*$G$19+C19*$G$20+D19*$G$21+E19*$G$22,"") -> 0.69307094 | I19: =IFERROR(H19/G19,"") -> 4.0812396
A20: =Справочник!$B$11 -> Бюджет | B20: =IF(C19="","",1/C19) -> 1 | C20: 1 | D20: 0.5 | E20: 2 | F20: =IF(COUNT(B20:E20)<4,"",GEOMEAN(B20:E20)) -> 1 | G20: =IFERROR(F20/SUM($F$19:$F$22),"") -> 0.2294591 | H20: =IFERROR(B20*$G$19+C20*$G$20+D20*$G$21+E20*$G$22,"") -> 0.94301704 | I20: =IFERROR(H20/G20,"") -> 4.1097392
A21: =Справочник!$B$12 -> Запись | B21: =IF(D19="","",1/D19) -> 3.3333333 | C21: =IF(D20="","",1/D20) -> 2 | D21: 1 | E21: 2 | F21: =IF(COUNT(B21:E21)<4,"",GEOMEAN(B21:E21)) -> 1.9108856 | G21: =IFERROR(F21/SUM($F$19:$F$22),"") -> 0.43847008 | H21: =IFERROR(B21*$G$19+C21*$G$20+D21*$G$21+E21*$G$22,"") -> 1.7879549 | I21: =IFERROR(H21/G21,"") -> 4.0777124
A22: =Справочник!$B$13 -> Привычки | B22: =IF(E19="","",1/E19) -> 1 | C22: =IF(E20="","",1/E20) -> 0.5 | D22: =IF(E21="","",1/E21) -> 0.5 | E22: 1 | F22: =IF(COUNT(B22:E22)<4,"",GEOMEAN(B22:E22)) -> 0.70710678 | G22: =IFERROR(F22/SUM($F$19:$F$22),"") -> 0.16225208 | H22: =IFERROR(B22*$G$19+C22*$G$20+D22*$G$21+E22*$G$22,"") -> 0.66603541 | I22: =IFERROR(H22/G22,"") -> 4.1049421
A23: lambda max | B23: =IF(COUNT(I19:I22)<4,"",AVERAGE(I19:I22)) -> 4.0934083 | C23: CI | D23: =IFERROR((B23-4)/(4-1),"") -> 0.031136104 | E23: CR (RI=0.9) | F23: =IFERROR(D23/0.9,"") -> 0.034595671 | G23: =IF(F23="","заполните матрицу",IF(F23<=0.1,"согласовано","CR > 0,1: пересмотреть")) -> согласовано
A30: ="Альтернативы по критерию: "&Справочник!$B$18 -> Альтернативы по критерию: Простота реализации MVP
B31: =Справочник!$B$10 -> Бронь | C31: =Справочник!$B$11 -> Бюджет | D31: =Справочник!$B$12 -> Запись | E31: =Справочник!$B$13 -> Привычки | F31: Среднее геом. строки | G31: Вес w | H31: (A*w)i | I31: (A*w)i / wi
A32: =Справочник!$B$10 -> Бронь | B32: 1 | C32: 3 | D32: 2 | E32: 1 | F32: =IF(COUNT(B32:E32)<4,"",GEOMEAN(B32:E32)) -> 1.5650846 | G32: =IFERROR(F32/SUM($F$32:$F$35),"") -> 0.36402351 | H32: =IFERROR(B32*$G$32+C32*$G$33+D32*$G$34+E32*$G$35,"") -> 1.4641565 | I32: =IFERROR(H32/G32,"") -> 4.0221483
A33: =Справочник!$B$11 -> Бюджет | B33: =IF(C32="","",1/C32) -> 0.33333333 | C33: 1 | D33: 1 | E33: 0.33333333 | F33: =IF(COUNT(B33:E33)<4,"",GEOMEAN(B33:E33)) -> 0.57735027 | G33: =IFERROR(F33/SUM($F$32:$F$35),"") -> 0.13428608 | H33: =IFERROR(B33*$G$32+C33*$G$33+D33*$G$34+E33*$G$35,"") -> 0.55324696 | I33: =IFERROR(H33/G33,"") -> 4.119913
A34: =Справочник!$B$12 -> Запись | B34: =IF(D32="","",1/D32) -> 0.5 | C34: =IF(D33="","",1/D33) -> 1 | D34: 1 | E34: 1 | F34: =IF(COUNT(B34:E34)<4,"",GEOMEAN(B34:E34)) -> 0.84089642 | G34: =IFERROR(F34/SUM($F$32:$F$35),"") -> 0.19558436 | H34: =IFERROR(B34*$G$32+C34*$G$33+D34*$G$34+E34*$G$35,"") -> 0.81798825 | I34: =IFERROR(H34/G34,"") -> 4.1822785
A35: =Справочник!$B$13 -> Привычки | B35: =IF(E32="","",1/E32) -> 1 | C35: =IF(E33="","",1/E33) -> 3 | D35: =IF(E34="","",1/E34) -> 1 | E35: 1 | F35: =IF(COUNT(B35:E35)<4,"",GEOMEAN(B35:E35)) -> 1.316074 | G35: =IFERROR(F35/SUM($F$32:$F$35),"") -> 0.30610606 | H35: =IFERROR(B35*$G$32+C35*$G$33+D35*$G$34+E35*$G$35,"") -> 1.2685722 | I35: =IFERROR(H35/G35,"") -> 4.1442242
A36: lambda max | B36: =IF(COUNT(I32:I35)<4,"",AVERAGE(I32:I35)) -> 4.117141 | C36: CI | D36: =IFERROR((B36-4)/(4-1),"") -> 0.039046999 | E36: CR (RI=0.9) | F36: =IFERROR(D36/0.9,"") -> 0.043385555 | G36: =IF(F36="","заполните матрицу",IF(F36<=0.1,"согласовано","CR > 0,1: пересмотреть")) -> согласовано
A43: ="Альтернативы по критерию: "&Справочник!$B$19 -> Альтернативы по критерию: Пригодность для оценки и планирования
B44: =Справочник!$B$10 -> Бронь | C44: =Справочник!$B$11 -> Бюджет | D44: =Справочник!$B$12 -> Запись | E44: =Справочник!$B$13 -> Привычки | F44: Среднее геом. строки | G44: Вес w | H44: (A*w)i | I44: (A*w)i / wi
A45: =Справочник!$B$10 -> Бронь | B45: 1 | C45: 3 | D45: 0.5 | E45: 3 | F45: =IF(COUNT(B45:E45)<4,"",GEOMEAN(B45:E45)) -> 1.4564753 | G45: =IFERROR(F45/SUM($F$45:$F$48),"") -> 0.29032191 | H45: =IFERROR(B45*$G$45+C45*$G$46+D45*$G$47+E45*$G$48,"") -> 1.1661236 | I45: =IFERROR(H45/G45,"") -> 4.0166571
A46: =Справочник!$B$11 -> Бюджет | B46: =IF(C45="","",1/C45) -> 0.33333333 | C46: 1 | D46: 0.2 | E46: 1 | F46: =IF(COUNT(B46:E46)<4,"",GEOMEAN(B46:E46)) -> 0.50813275 | G46: =IFERROR(F46/SUM($F$45:$F$48),"") -> 0.10128704 | H46: =IFERROR(B46*$G$45+C46*$G$46+D46*$G$47+E46*$G$48,"") -> 0.40541762 | I46: =IFERROR(H46/G46,"") -> 4.0026605
A47: =Справочник!$B$12 -> Запись | B47: =IF(D45="","",1/D45) -> 2 | C47: =IF(D46="","",1/D46) -> 5 | D47: 1 | E47: 4 | F47: =IF(COUNT(B47:E47)<4,"",GEOMEAN(B47:E47)) -> 2.5148669 | G47: =IFERROR(F47/SUM($F$45:$F$48),"") -> 0.50129305 | H47: =IFERROR(B47*$G$45+C47*$G$46+D47*$G$47+E47*$G$48,"") -> 2.0167641 | I47: =IFERROR(H47/G47,"") -> 4.023124
A48: =Справочник!$B$13 -> Привычки | B48: =IF(E45="","",1/E45) -> 0.33333333 | C48: =IF(E46="","",1/E46) -> 1 | D48: =IF(E47="","",1/E47) -> 0.25 | E48: 1 | F48: =IF(COUNT(B48:E48)<4,"",GEOMEAN(B48:E48)) -> 0.53728497 | G48: =IFERROR(F48/SUM($F$45:$F$48),"") -> 0.107098 | H48: =IFERROR(B48*$G$45+C48*$G$46+D48*$G$47+E48*$G$48,"") -> 0.43048227 | I48: =IFERROR(H48/G48,"") -> 4.0195173
A49: lambda max | B49: =IF(COUNT(I45:I48)<4,"",AVERAGE(I45:I48)) -> 4.0154897 | C49: CI | D49: =IFERROR((B49-4)/(4-1),"") -> 0.00516323 | E49: CR (RI=0.9) | F49: =IFERROR(D49/0.9,"") -> 0.0057369222 | G49: =IF(F49="","заполните матрицу",IF(F49<=0.1,"согласовано","CR > 0,1: пересмотреть")) -> согласовано
A56: ="Альтернативы по критерию: "&Справочник!$B$20 -> Альтернативы по критерию: Потенциал монетизации
B57: =Справочник!$B$10 -> Бронь | C57: =Справочник!$B$11 -> Бюджет | D57: =Справочник!$B$12 -> Запись | E57: =Справочник!$B$13 -> Привычки | F57: Среднее геом. строки | G57: Вес w | H57: (A*w)i | I57: (A*w)i / wi
A58: =Справочник!$B$10 -> Бронь | B58: 1 | C58: 1 | D58: 0.25 | E58: 2 | F58: =IF(COUNT(B58:E58)<4,"",GEOMEAN(B58:E58)) -> 0.84089642 | G58: =IFERROR(F58/SUM($F$58:$F$61),"") -> 0.16783623 | H58: =IFERROR(B58*$G$58+C58*$G$59+D58*$G$60+E58*$G$61,"") -> 0.67639737 | I58: =IFERROR(H58/G58,"") -> 4.0301035
A59: =Справочник!$B$11 -> Бюджет | B59: =IF(C58="","",1/C58) -> 1 | C59: 1 | D59: 0.25 | E59: 2 | F59: =IF(COUNT(B59:E59)<4,"",GEOMEAN(B59:E59)) -> 0.84089642 | G59: =IFERROR(F59/SUM($F$58:$F$61),"") -> 0.16783623 | H59: =IFERROR(B59*$G$58+C59*$G$59+D59*$G$60+E59*$G$61,"") -> 0.67639737 | I59: =IFERROR(H59/G59,"") -> 4.0301035
A60: =Справочник!$B$12 -> Запись | B60: =IF(D58="","",1/D58) -> 4 | C60: =IF(D59="","",1/D59) -> 4 | D60: 1 | E60: 4 | F60: =IF(COUNT(B60:E60)<4,"",GEOMEAN(B60:E60)) -> 2.8284271 | G60: =IFERROR(F60/SUM($F$58:$F$61),"") -> 0.56453153 | H60: =IFERROR(B60*$G$58+C60*$G$59+D60*$G$60+E60*$G$61,"") -> 2.3064054 | I60: =IFERROR(H60/G60,"") -> 4.085521
A61: =Справочник!$B$13 -> Привычки | B61: =IF(E58="","",1/E58) -> 0.5 | C61: =IF(E59="","",1/E59) -> 0.5 | D61: =IF(E60="","",1/E60) -> 0.25 | E61: 1 | F61: =IF(COUNT(B61:E61)<4,"",GEOMEAN(B61:E61)) -> 0.5 | G61: =IFERROR(F61/SUM($F$58:$F$61),"") -> 0.099796018 | H61: =IFERROR(B61*$G$58+C61*$G$59+D61*$G$60+E61*$G$61,"") -> 0.40876513 | I61: =IFERROR(H61/G61,"") -> 4.0960064
A62: lambda max | B62: =IF(COUNT(I58:I61)<4,"",AVERAGE(I58:I61)) -> 4.0604336 | C62: CI | D62: =IFERROR((B62-4)/(4-1),"") -> 0.020144539 | E62: CR (RI=0.9) | F62: =IFERROR(D62/0.9,"") -> 0.022382821 | G62: =IF(F62="","заполните матрицу",IF(F62<=0.1,"согласовано","CR > 0,1: пересмотреть")) -> согласовано
A69: ="Альтернативы по критерию: "&Справочник!$B$21 -> Альтернативы по критерию: Интерес и экспертиза команды
B70: =Справочник!$B$10 -> Бронь | C70: =Справочник!$B$11 -> Бюджет | D70: =Справочник!$B$12 -> Запись | E70: =Справочник!$B$13 -> Привычки | F70: Среднее геом. строки | G70: Вес w | H70: (A*w)i | I70: (A*w)i / wi
...

Sheet Коллективный
A1: Четкий коллективный МАИ: агрегирование индивидуальных суждений средним геометрическим (AIJ)
A2: a_ij = GEOMEAN(a_ij эксперта 1, 2, 3); веса - нормированное среднее геометрическое строк; CR = CI/RI
A4: Критерии (относительно цели: выбор концепции)
B5: =Справочник!$B$17 -> Востребованность | C5: =Справочник!$B$18 -> Простота реализации MVP | D5: =Справочник!$B$19 -> Пригодность для оценки и планирования | E5: =Справочник!$B$20 -> Потенциал монетизации | F5: =Справочник!$B$21 -> Интерес и экспертиза команды | G5: Среднее геом. строки | H5: Вес w | I5: (A*w)i | J5: (A*w)i / wi
A6: =Справочник!$B$17 -> Востребованность | B6: =IF(COUNT(Эксперт1!B6,Эксперт2!B6,Эксперт3!B6)<3,"",GEOMEAN(Эксперт1!B6,Эксперт2!B6,Эксперт3!B6)) -> 1 | C6: =IF(COUNT(Эксперт1!C6,Эксперт2!C6,Эксперт3!C6)<3,"",GEOMEAN(Эксперт1!C6,Эксперт2!C6,Эксперт3!C6)) -> 0.5 | D6: =IF(COUNT(Эксперт1!D6,Эксперт2!D6,Эксперт3!D6)<3,"",GEOMEAN(Эксперт1!D6,Эксперт2!D6,Эксперт3!D6)) -> 0.36840315 | E6: =IF(COUNT(Эксперт1!E6,Эксперт2!E6,Эксперт3!E6)<3,"",GEOMEAN(Эксперт1!E6,Эксперт2!E6,Эксперт3!E6)) -> 2 | F6: =IF(COUNT(Эксперт1!F6,Эксперт2!F6,Эксперт3!F6)<3,"",GEOMEAN(Эксперт1!F6,Эксперт2!F6,Эксперт3!F6)) -> 1 | G6: =IF(COUNT(B6:F6)<5,"",GEOMEAN(B6:F6)) -> 0.81896373 | H6: =IFERROR(G6/SUM($G$6:$G$10),"") -> 0.14236177 | I6: =IFERROR(B6*$H$6+C6*$H$7+D6*$H$8+E6*$H$9+F6*$H$10,"") -> 0.71669951 | J6: =IFERROR(I6/H6,"") -> 5.0343538
A7: =Справочник!$B$18 -> Простота реализации MVP | B7: =IF(COUNT(Эксперт1!B7,Эксперт2!B7,Эксперт3!B7)<3,"",GEOMEAN(Эксперт1!B7,Эксперт2!B7,Эксперт3!B7)) -> 2 | C7: =IF(COUNT(Эксперт1!C7,Эксперт2!C7,Эксперт3!C7)<3,"",GEOMEAN(Эксперт1!C7,Эксперт2!C7,Эксперт3!C7)) -> 1 | D7: =IF(COUNT(Эксперт1!D7,Эксперт2!D7,Эксперт3!D7)<3,"",GEOMEAN(Эксперт1!D7,Эксперт2!D7,Эксперт3!D7)) -> 0.43088694 | E7: =IF(COUNT(Эксперт1!E7,Эксперт2!E7,Эксперт3!E7)<3,"",GEOMEAN(Эксперт1!E7,Эксперт2!E7,Эксперт3!E7)) -> 2.6207414 | F7: =IF(COUNT(Эксперт1!F7,Эксперт2!F7,Эксперт3!F7)<3,"",GEOMEAN(Эксперт1!F7,Эксперт2!F7,Эксперт3!F7)) -> 2 | G7: =IF(COUNT(B7:F7)<5,"",GEOMEAN(B7:F7)) -> 1.3519776 | H7: =IFERROR(G7/SUM($G$6:$G$10),"") -> 0.23501642 | I7: =IFERROR(B7*$H$6+C7*$H$7+D7*$H$8+E7*$H$9+F7*$H$10,"") -> 1.1947583 | J7: =IFERROR(I7/H7,"") -> 5.0837227
A8: =Справочник!$B$19 -> Пригодность для оценки и планирования | B8: =IF(COUNT(Эксперт1!B8,Эксперт2!B8,Эксперт3!B8)<3,"",GEOMEAN(Эксперт1!B8,Эксперт2!B8,Эксперт3!B8)) -> 2.7144176 | C8: =IF(COUNT(Эксперт1!C8,Эксперт2!C8,Эксперт3!C8)<3,"",GEOMEAN(Эксперт1!C8,Эксперт2!C8,Эксперт3!C8)) -> 2.3207944 | D8: =IF(COUNT(Эксперт1!D8,Эксперт2!D8,Эксперт3!D8)<3,"",GEOMEAN(Эксперт1!D8,Эксперт2!D8,Эксперт3!D8)) -> 1 | E8: =IF(COUNT(Эксперт1!E8,Эксперт2!E8,Эксперт3!E8)<3,"",GEOMEAN(Эксперт1!E8,Эксперт2!E8,Эксперт3!E8)) -> 4.3088694 | F8: =IF(COUNT(Эксперт1!F8,Эксперт2!F8,Эксперт3!F8)<3,"",GEOMEAN(Эксперт1!F8,Эксперт2!F8,Эксперт3!F8)) -> 2.2894285 | G8: =IF(COUNT(B8:F8)<5,"",GEOMEAN(B8:F8)) -> 2.2839193 | H8: =IFERROR(G8/SUM($G$6:$G$10),"") -> 0.39701733 | I8: =IFERROR(B8*$H$6+C8*$H$7+D8*$H$8+E8*$H$9+F8*$H$10,"") -> 2.0169537 | J8: =IFERROR(I8/H8,"") -> 5.0802663
A9: =Справочник!$B$20 -> Потенциал монетизации | B9: =IF(COUNT(Эксперт1!B9,Эксперт2!B9,Эксперт3!B9)<3,"",GEOMEAN(Эксперт1!B9,Эксперт2!B9,Эксперт3!B9)) -> 0.5 | C9: =IF(COUNT(Эксперт1!C9,Эксперт2!C9,Эксперт3!C9)<3,"",GEOMEAN(Эксперт1!C9,Эксперт2!C9,Эксперт3!C9)) -> 0.38157141 | D9: =IF(COUNT(Эксперт1!D9,Эксперт2!D9,Эксперт3!D9)<3,"",GEOMEAN(Эксперт1!D9,Эксперт2!D9,Эксперт3!D9)) -> 0.23207944 | E9: =IF(COUNT(Эксперт1!E9,Эксперт2!E9,Эксперт3!E9)<3,"",GEOMEAN(Эксперт1!E9,Эксперт2!E9,Эксперт3!E9)) -> 1 | F9: =IF(COUNT(Эксперт1!F9,Эксперт2!F9,Эксперт3!F9)<3,"",GEOMEAN(Эксперт1!F9,Эксперт2!F9,Эксперт3!F9)) -> 0.62996052 | G9: =IF(COUNT(B9:F9)<5,"",GEOMEAN(B9:F9)) -> 0.48876395 | H9: =IFERROR(G9/SUM($G$6:$G$10),"") -> 0.084962616 | I9: =IFERROR(B9*$H$6+C9*$H$7+D9*$H$8+E9*$H$9+F9*$H$10,"") -> 0.42655743 | J9: =IFERROR(I9/H9,"") -> 5.0205308
A10: =Справочник!$B$21 -> Интерес и экспертиза команды | B10: =IF(COUNT(Эксперт1!B10,Эксперт2!B10,Эксперт3!B10)<3,"",GEOMEAN(Эксперт1!B10,Эксперт2!B10,Эксперт3!B10)) -> 1 | C10: =IF(COUNT(Эксперт1!C10,Эксперт2!C10,Эксперт3!C10)<3,"",GEOMEAN(Эксперт1!C10,Эксперт2!C10,Эксперт3!C10)) -> 0.5 | D10: =IF(COUNT(Эксперт1!D10,Эксперт2!D10,Эксперт3!D10)<3,"",GEOMEAN(Эксперт1!D10,Эксперт2!D10,Эксперт3!D10)) -> 0.43679023 | E10: =IF(COUNT(Эксперт1!E10,Эксперт2!E10,Эксперт3!E10)<3,"",GEOMEAN(Эксперт1!E10,Эксперт2!E10,Эксперт3!E10)) -> 1.5874011 | F10: =IF(COUNT(Эксперт1!F10,Эксперт2!F10,Эксперт3!F10)<3,"",GEOMEAN(Эксперт1!F10,Эксперт2!F10,Эксперт3!F10)) -> 1 | G10: =IF(COUNT(B10:F10)<5,"",GEOMEAN(B10:F10)) -> 0.80906966 | H10: =IFERROR(G10/SUM($G$6:$G$10),"") -> 0.14064187 | I10: =IFERROR(B10*$H$6+C10*$H$7+D10*$H$8+E10*$H$9+F10*$H$10,"") -> 0.70879488 | J10: =IFERROR(I10/H10,"") -> 5.0397147
A11: lambda max | B11: =IF(COUNT(J6:J10)<5,"",AVERAGE(J6:J10)) -> 5.0517177 | C11: CI | D11: =IFERROR((B11-5)/(5-1),"") -> 0.012929414 | E11: CR (RI=1.12) | F11: =IFERROR(D11/1.12,"") -> 0.01154412 | G11: =IF(F11="","заполните матрицу",IF(F11<=0.1,"согласовано","CR > 0,1: пересмотреть")) -> согласовано
A17: ="Альтернативы по критерию: "&Справочник!$B$17 -> Альтернативы по критерию: Востребованность
B18: =Справочник!$B$10 -> Бронь | C18: =Справочник!$B$11 -> Бюджет | D18: =Справочник!$B$12 -> Запись | E18: =Справочник!$B$13 -> Привычки | F18: Среднее геом. строки | G18: Вес w | H18: (A*w)i | I18: (A*w)i / wi
A19: =Справочник!$B$10 -> Бронь | B19: =IF(COUNT(Эксперт1!B19,Эксперт2!B19,Эксперт3!B19)<3,"",GEOMEAN(Эксперт1!B19,Эксперт2!B19,Эксперт3!B19)) -> 1 | C19: =IF(COUNT(Эксперт1!C19,Эксперт2!C19,Эксперт3!C19)<3,"",GEOMEAN(Эксперт1!C19,Эксперт2!C19,Эксперт3!C19)) -> 0.79370053 | D19: =IF(COUNT(Эксперт1!D19,Эксперт2!D19,Эксперт3!D19)<3,"",GEOMEAN(Эксперт1!D19,Эксперт2!D19,Эксперт3!D19)) -> 0.31072325 | E19: =IF(COUNT(Эксперт1!E19,Эксперт2!E19,Эксперт3!E19)<3,"",GEOMEAN(Эксперт1!E19,Эксперт2!E19,Эксперт3!E19)) -> 1 | F19: =IF(COUNT(B19:E19)<4,"",GEOMEAN(B19:E19)) -> 0.70470541 | G19: =IFERROR(F19/SUM($F$19:$F$22),"") -> 0.16058932 | H19: =IFERROR(B19*$G$19+C19*$G$20+D19*$G$21+E19*$G$22,"") -> 0.64523785 | I19: =IFERROR(H19/G19,"") -> 4.0179375
A20: =Справочник!$B$11 -> Бюджет | B20: =IF(COUNT(Эксперт1!B20,Эксперт2!B20,Эксперт3!B20)<3,"",GEOMEAN(Эксперт1!B20,Эксперт2!B20,Эксперт3!B20)) -> 1.259921 | C20: =IF(COUNT(Эксперт1!C20,Эксперт2!C20,Эксперт3!C20)<3,"",GEOMEAN(Эксперт1!C20,Эксперт2!C20,Эксперт3!C20)) -> 1 | D20: =IF(COUNT(Эксперт1!D20,Эксперт2!D20,Эксперт3!D20)<3,"",GEOMEAN(Эксперт1!D20,Эксперт2!D20,Эксперт3!D20)) -> 0.5 | E20: =IF(COUNT(Эксперт1!E20,Эксперт2!E20,Эксперт3!E20)<3,"",GEOMEAN(Эксперт1!E20,Эксперт2!E20,Эксперт3!E20)) -> 1.5874011 | F20: =IF(COUNT(B20:E20)<4,"",GEOMEAN(B20:E20)) -> 1 | G20: =IFERROR(F20/SUM($F$19:$F$22),"") -> 0.22788149 | H20: =IFERROR(B20*$G$19+C20*$G$20+D20*$G$21+E20*$G$22,"") -> 0.9154474 | I20: =IFERROR(H20/G20,"") -> 4.0172082
A21: =Справочник!$B$12 -> Запись | B21: =IF(COUNT(Эксперт1!B21,Эксперт2!B21,Эксперт3!B21)<3,"",GEOMEAN(Эксперт1!B21,Эксперт2!B21,Эксперт3!B21)) -> 3.2182979 | C21: =IF(COUNT(Эксперт1!C21,Эксперт2!C21,Эксперт3!C21)<3,"",GEOMEAN(Эксперт1!C21,Эксперт2!C21,Эксперт3!C21)) -> 2 | D21: =IF(COUNT(Эксперт1!D21,Эксперт2!D21,Эксперт3!D21)<3,"",GEOMEAN(Эксперт1!D21,Эксперт2!D21,Эксперт3!D21)) -> 1 | E21: =IF(COUNT(Эксперт1!E21,Эксперт2!E21,Эксперт3!E21)<3,"",GEOMEAN(Эксперт1!E21,Эксперт2!E21,Эксперт3!E21)) -> 2.2894285 | F21: =IF(COUNT(B21:E21)<4,"",GEOMEAN(B21:E21)) -> 1.959277 | G21: =IFERROR(F21/SUM($F$19:$F$22),"") -> 0.44648296 | H21: =IFERROR(B21*$G$19+C21*$G$20+D21*$G$21+E21*$G$22,"") -> 1.7969318 | I21: =IFERROR(H21/G21,"") -> 4.0246369
A22: =Справочник!$B$13 -> Привычки | B22: =IF(COUNT(Эксперт1!B22,Эксперт2!B22,Эксперт3!B22)<3,"",GEOMEAN(Эксперт1!B22,Эксперт2!B22,Эксперт3!B22)) -> 1 | C22: =IF(COUNT(Эксперт1!C22,Эксперт2!C22,Эксперт3!C22)<3,"",GEOMEAN(Эксперт1!C22,Эксперт2!C22,Эксперт3!C22)) -> 0.62996052 | D22: =IF(COUNT(Эксперт1!D22,Эксперт2!D22,Эксперт3!D22)<3,"",GEOMEAN(Эксперт1!D22,Эксперт2!D22,Эксперт3!D22)) -> 0.43679023 | E22: =IF(COUNT(Эксперт1!E22,Эксперт2!E22,Эксперт3!E22)<3,"",GEOMEAN(Эксперт1!E22,Эксперт2!E22,Эксперт3!E22)) -> 1 | F22: =IF(COUNT(B22:E22)<4,"",GEOMEAN(B22:E22)) -> 0.72426344 | G22: =IFERROR(F22/SUM($F$19:$F$22),"") -> 0.16504623 | H22: =IFERROR(B22*$G$19+C22*$G$20+D22*$G$21+E22*$G$22,"") -> 0.66421129 | I22: =IFERROR(H22/G22,"") -> 4.0243953
A23: lambda max | B23: =IF(COUNT(I19:I22)<4,"",AVERAGE(I19:I22)) -> 4.0210445 | C23: CI | D23: =IFERROR((B23-4)/(4-1),"") -> 0.0070148248 | E23: CR (RI=0.9) | F23: =IFERROR(D23/0.9,"") -> 0.0077942498 | G23: =IF(F23="","заполните матрицу",IF(F23<=0.1,"согласовано","CR > 0,1: пересмотреть")) -> согласовано
A30: ="Альтернативы по критерию: "&Справочник!$B$18 -> Альтернативы по критерию: Простота реализации MVP
B31: =Справочник!$B$10 -> Бронь | C31: =Справочник!$B$11 -> Бюджет | D31: =Справочник!$B$12 -> Запись | E31: =Справочник!$B$13 -> Привычки | F31: Среднее геом. строки | G31: Вес w | H31: (A*w)i | I31: (A*w)i / wi
A32: =Справочник!$B$10 -> Бронь | B32: =IF(COUNT(Эксперт1!B32,Эксперт2!B32,Эксперт3!B32)<3,"",GEOMEAN(Эксперт1!B32,Эксперт2!B32,Эксперт3!B32)) -> 1 | C32: =IF(COUNT(Эксперт1!C32,Эксперт2!C32,Эксперт3!C32)<3,"",GEOMEAN(Эксперт1!C32,Эксперт2!C32,Эксперт3!C32)) -> 2.6207414 | D32: =IF(COUNT(Эксперт1!D32,Эксперт2!D32,Эксперт3!D32)<3,"",GEOMEAN(Эксперт1!D32,Эксперт2!D32,Эксперт3!D32)) -> 2 | E32: =IF(COUNT(Эксперт1!E32,Эксперт2!E32,Эксперт3!E32)<3,"",GEOMEAN(Эксперт1!E32,Эксперт2!E32,Эксперт3!E32)) -> 0.79370053 | F32: =IF(COUNT(B32:E32)<4,"",GEOMEAN(B32:E32)) -> 1.4281628 | G32: =IFERROR(F32/SUM($F$32:$F$35),"") -> 0.33297273 | H32: =IFERROR(B32*$G$32+C32*$G$33+D32*$G$34+E32*$G$35,"") -> 1.3582845 | I32: =IFERROR(H32/G32,"") -> 4.0792665
A33: =Справочник!$B$11 -> Бюджет | B33: =IF(COUNT(Эксперт1!B33,Эксперт2!B33,Эксперт3!B33)<3,"",GEOMEAN(Эксперт1!B33,Эксперт2!B33,Эксперт3!B33)) -> 0.38157141 | C33: =IF(COUNT(Эксперт1!C33,Эксперт2!C33,Эксперт3!C33)<3,"",GEOMEAN(Эксперт1!C33,Эксперт2!C33,Эксперт3!C33)) -> 1 | D33: =IF(COUNT(Эксперт1!D33,Эксперт2!D33,Эксперт3!D33)<3,"",GEOMEAN(Эксперт1!D33,Эксперт2!D33,Эксперт3!D33)) -> 0.66943295 | E33: =IF(COUNT(Эксперт1!E33,Эксперт2!E33,Эксперт3!E33)<3,"",GEOMEAN(Эксперт1!E33,Эксперт2!E33,Эксперт3!E33)) -> 0.32182979 | F33: =IF(COUNT(B33:E33)<4,"",GEOMEAN(B33:E33)) -> 0.53546032 | G33: =IFERROR(F33/SUM($F$32:$F$35),"") -> 0.12484129 | H33: =IFERROR(B33*$G$32+C33*$G$33+D33*$G$34+E33*$G$35,"") -> 0.5035546 | I33: =IFERROR(H33/G33,"") -> 4.0335582
A34: =Справочник!$B$12 -> Запись | B34: =IF(COUNT(Эксперт1!B34,Эксперт2!B34,Эксперт3!B34)<3,"",GEOMEAN(Эксперт1!B34,Эксперт2!B34,Эксперт3!B34)) -> 0.5 | C34: =IF(COUNT(Эксперт1!C34,Эксперт2!C34,Эксперт3!C34)<3,"",GEOMEAN(Эксперт1!C34,Эксперт2!C34,Эксперт3!C34)) -> 1.4938016 | D34: =IF(COUNT(Эксперт1!D34,Эксперт2!D34,Эксперт3!D34)<3,"",GEOMEAN(Эксперт1!D34,Эксперт2!D34,Эксперт3!D34)) -> 1 | E34: =IF(COUNT(Эксперт1!E34,Эксперт2!E34,Эксперт3!E34)<3,"",GEOMEAN(Эксперт1!E34,Эксперт2!E34,Эксперт3!E34)) -> 1.1006424 | F34: =IF(COUNT(B34:E34)<4,"",GEOMEAN(B34:E34)) -> 0.95219806 | G34: =IFERROR(F34/SUM($F$32:$F$35),"") -> 0.22200269 | H34: =IFERROR(B34*$G$32+C34*$G$33+D34*$G$34+E34*$G$35,"") -> 0.92738448 | I34: =IFERROR(H34/G34,"") -> 4.1773569
A35: =Справочник!$B$13 -> Привычки | B35: =IF(COUNT(Эксперт1!B35,Эксперт2!B35,Эксперт3!B35)<3,"",GEOMEAN(Эксперт1!B35,Эксперт2!B35,Эксперт3!B35)) -> 1.259921 | C35: =IF(COUNT(Эксперт1!C35,Эксперт2!C35,Эксперт3!C35)<3,"",GEOMEAN(Эксперт1!C35,Эксперт2!C35,Эксперт3!C35)) -> 3.1072325 | D35: =IF(COUNT(Эксперт1!D35,Эксперт2!D35,Эксперт3!D35)<3,"",GEOMEAN(Эксперт1!D35,Эксперт2!D35,Эксперт3!D35)) -> 0.9085603 | E35: =IF(COUNT(Эксперт1!E35,Эксперт2!E35,Эксперт3!E35)<3,"",GEOMEAN(Эксперт1!E35,Эксперт2!E35,Эксперт3!E35)) -> 1 | F35: =IF(COUNT(B35:E35)<4,"",GEOMEAN(B35:E35)) -> 1.3733072 | G35: =IFERROR(F35/SUM($F$32:$F$35),"") -> 0.32018329 | H35: =IFERROR(B35*$G$32+C35*$G$33+D35*$G$34+E35*$G$35,"") -> 1.3293164 | I35: =IFERROR(H35/G35,"") -> 4.1517357
A36: lambda max | B36: =IF(COUNT(I32:I35)<4,"",AVERAGE(I32:I35)) -> 4.1104793 | C36: CI | D36: =IFERROR((B36-4)/(4-1),"") -> 0.036826438 | E36: CR (RI=0.9) | F36: =IFERROR(D36/0.9,"") -> 0.040918264 | G36: =IF(F36="","заполните матрицу",IF(F36<=0.1,"согласовано","CR > 0,1: пересмотреть")) -> согласовано
A43: ="Альтернативы по критерию: "&Справочник!$B$19 -> Альтернативы по критерию: Пригодность для оценки и планирования
B44: =Справочник!$B$10 -> Бронь | C44: =Справочник!$B$11 -> Бюджет | D44: =Справочник!$B$12 -> Запись | E44: =Справочник!$B$13 -> Привычки | F44: Среднее геом. строки | G44: Вес w | H44: (A*w)i | I44: (A*w)i / wi
A45: =Справочник!$B$10 -> Бронь | B45: =IF(COUNT(Эксперт1!B45,Эксперт2!B45,Эксперт3!B45)<3,"",GEOMEAN(Эксперт1!B45,Эксперт2!B45,Эксперт3!B45)) -> 1 | C45: =IF(COUNT(Эксперт1!C45,Эксперт2!C45,Эксперт3!C45)<3,"",GEOMEAN(Эксперт1!C45,Эксперт2!C45,Эксперт3!C45)) -> 3 | D45: =IF(COUNT(Эксперт1!D45,Эксперт2!D45,Эксперт3!D45)<3,"",GEOMEAN(Эксперт1!D45,Эксперт2!D45,Эксперт3!D45)) -> 0.5 | E45: =IF(COUNT(Эксперт1!E45,Эксперт2!E45,Эксперт3!E45)<3,"",GEOMEAN(Эксперт1!E45,Эксперт2!E45,Эксперт3!E45)) -> 3 | F45: =IF(COUNT(B45:E45)<4,"",GEOMEAN(B45:E45)) -> 1.4564753 | G45: =IFERROR(F45/SUM($F$45:$F$48),"") -> 0.292467 | H45: =IFERROR(B45*$G$45+C45*$G$46+D45*$G$47+E45*$G$48,"") -> 1.1758331 | I45: =IFERROR(H45/G45,"") -> 4.0203959
A46: =Справочник!$B$11 -> Бюджет | B46: =IF(COUNT(Эксперт1!B46,Эксперт2!B46,Эксперт3!B46)<3,"",GEOMEAN(Эксперт1!B46,Эксперт2!B46,Эксперт3!B46)) -> 0.33333333 | C46: =IF(COUNT(Эксперт1!C46,Эксперт2!C46,Эксперт3!C46)<3,"",GEOMEAN(Эксперт1!C46,Эксперт2!C46,Эксперт3!C46)) -> 1 | D46: =IF(COUNT(Эксперт1!D46,Эксперт2!D46,Эксперт3!D46)<3,"",GEOMEAN(Эксперт1!D46,Эксперт2!D46,Эксперт3!D46)) -> 0.21544347 | E46: =IF(COUNT(Эксперт1!E46,Эксперт2!E46,Эксперт3!E46)<3,"",GEOMEAN(Эксперт1!E46,Эксперт2!E46,Эксперт3!E46)) -> 1 | F46: =IF(COUNT(B46:E46)<4,"",GEOMEAN(B46:E46)) -> 0.51767003 | G46: =IFERROR(F46/SUM($F$45:$F$48),"") -> 0.10395054 | H46: =IFERROR(B46*$G$45+C46*$G$46+D46*$G$47+E46*$G$48,"") -> 0.41612271 | I46: =IFERROR(H46/G46,"") -> 4.0030835
A47: =Справочник!$B$12 -> Запись | B47: =IF(COUNT(Эксперт1!B47,Эксперт2!B47,Эксперт3!B47)<3,"",GEOMEAN(Эксперт1!B47,Эксперт2!B47,Эксперт3!B47)) -> 2 | C47: =IF(COUNT(Эксперт1!C47,Эксперт2!C47,Эксперт3!C47)<3,"",GEOMEAN(Эксперт1!C47,Эксперт2!C47,Эксперт3!C47)) -> 4.6415888 | D47: =IF(COUNT(Эксперт1!D47,Эксперт2!D47,Эксперт3!D47)<3,"",GEOMEAN(Эксперт1!D47,Эксперт2!D47,Эксперт3!D47)) -> 1 | E47: =IF(COUNT(Эксперт1!E47,Эксперт2!E47,Эксперт3!E47)<3,"",GEOMEAN(Эксперт1!E47,Эксперт2!E47,Эксперт3!E47)) -> 4 | F47: =IF(COUNT(B47:E47)<4,"",GEOMEAN(B47:E47)) -> 2.4685343 | G47: =IFERROR(F47/SUM($F$45:$F$48),"") -> 0.49569314 | H47: =IFERROR(B47*$G$45+C47*$G$46+D47*$G$47+E47*$G$48,"") -> 1.9946801 | I47: =IFERROR(H47/G47,"") -> 4.024022
A48: =Справочник!$B$13 -> Привычки | B48: =IF(COUNT(Эксперт1!B48,Эксперт2!B48,Эксперт3!B48)<3,"",GEOMEAN(Эксперт1!B48,Эксперт2!B48,Эксперт3!B48)) -> 0.33333333 | C48: =IF(COUNT(Эксперт1!C48,Эксперт2!C48,Эксперт3!C48)<3,"",GEOMEAN(Эксперт1!C48,Эксперт2!C48,Эксперт3!C48)) -> 1 | D48: =IF(COUNT(Эксперт1!D48,Эксперт2!D48,Эксперт3!D48)<3,"",GEOMEAN(Эксперт1!D48,Эксперт2!D48,Эксперт3!D48)) -> 0.25 | E48: =IF(COUNT(Эксперт1!E48,Эксперт2!E48,Эксперт3!E48)<3,"",GEOMEAN(Эксперт1!E48,Эксперт2!E48,Эксперт3!E48)) -> 1 | F48: =IF(COUNT(B48:E48)<4,"",GEOMEAN(B48:E48)) -> 0.53728497 | G48: =IFERROR(F48/SUM($F$45:$F$48),"") -> 0.10788931 | H48: =IFERROR(B48*$G$45+C48*$G$46+D48*$G$47+E48*$G$48,"") -> 0.43325214 | I48: =IFERROR(H48/G48,"") -> 4.0157095
A49: lambda max | B49: =IF(COUNT(I45:I48)<4,"",AVERAGE(I45:I48)) -> 4.0158027 | C49: CI | D49: =IFERROR((B49-4)/(4-1),"") -> 0.0052675762 | E49: CR (RI=0.9) | F49: =IFERROR(D49/0.9,"") -> 0.0058528625 | G49: =IF(F49="","заполните матрицу",IF(F49<=0.1,"согласовано","CR > 0,1: пересмотреть")) -> согласовано
A56: ="Альтернативы по критерию: "&Справочник!$B$20 -> Альтернативы по критерию: Потенциал монетизации
B57: =Справочник!$B$10 -> Бронь | C57: =Справочник!$B$11 -> Бюджет | D57: =Справочник!$B$12 -> Запись | E57: =Справочник!$B$13 -> Привычки | F57: Среднее геом. строки | G57: Вес w | H57: (A*w)i | I57: (A*w)i / wi
A58: =Справочник!$B$10 -> Бронь | B58: =IF(COUNT(Эксперт1!B58,Эксперт2!B58,Эксперт3!B58)<3,"",GEOMEAN(Эксперт1!B58,Эксперт2!B58,Эксперт3!B58)) -> 1 | C58: =IF(COUNT(Эксперт1!C58,Эксперт2!C58,Эксперт3!C58)<3,"",GEOMEAN(Эксперт1!C58,Эксперт2!C58,Эксперт3!C58)) -> 1 | D58: =IF(COUNT(Эксперт1!D58,Эксперт2!D58,Эксперт3!D58)<3,"",GEOMEAN(Эксперт1!D58,Эксперт2!D58,Эксперт3!D58)) -> 0.25 | E58: =IF(COUNT(Эксперт1!E58,Эксперт2!E58,Эксперт3!E58)<3,"",GEOMEAN(Эксперт1!E58,Эксперт2!E58,Эксперт3!E58)) -> 2 | F58: =IF(COUNT(B58:E58)<4,"",GEOMEAN(B58:E58)) -> 0.84089642 | G58: =IFERROR(F58/SUM($F$58:$F$61),"") -> 0.16801847 | H58: =IFERROR(B58*$G$58+C58*$G$59+D58*$G$60+E58*$G$61,"") -> 0.67859223 | I58: =IFERROR(H58/G58,"") -> 4.0387953
A59: =Справочник!$B$11 -> Бюджет | B59: =IF(COUNT(Эксперт1!B59,Эксперт2!B59,Эксперт3!B59)<3,"",GEOMEAN(Эксперт1!B59,Эксперт2!B59,Эксперт3!B59)) -> 1 | C59: =IF(COUNT(Эксперт1!C59,Эксперт2!C59,Эксперт3!C59)<3,"",GEOMEAN(Эксперт1!C59,Эксперт2!C59,Эксперт3!C59)) -> 1 | D59: =IF(COUNT(Эксперт1!D59,Эксперт2!D59,Эксперт3!D59)<3,"",GEOMEAN(Эксперт1!D59,Эксперт2!D59,Эксперт3!D59)) -> 0.26566464 | E59: =IF(COUNT(Эксперт1!E59,Эксперт2!E59,Эксперт3!E59)<3,"",GEOMEAN(Эксперт1!E59,Эксперт2!E59,Эксперт3!E59)) -> 1.5874011 | F59: =IF(COUNT(B59:E59)<4,"",GEOMEAN(B59:E59)) -> 0.80585166 | G59: =IFERROR(F59/SUM($F$58:$F$61),"") -> 0.16101622 | H59: =IFERROR(B59*$G$58+C59*$G$59+D59*$G$60+E59*$G$61,"") -> 0.64460822 | I59: =IFERROR(H59/G59,"") -> 4.0033744
A60: =Справочник!$B$12 -> Запись | B60: =IF(COUNT(Эксперт1!B60,Эксперт2!B60,Эксперт3!B60)<3,"",GEOMEAN(Эксперт1!B60,Эксперт2!B60,Эксперт3!B60)) -> 4 | C60: =IF(COUNT(Эксперт1!C60,Эксперт2!C60,Эксперт3!C60)<3,"",GEOMEAN(Эксперт1!C60,Эксперт2!C60,Эксперт3!C60)) -> 3.7641441 | D60: =IF(COUNT(Эксперт1!D60,Эксперт2!D60,Эксперт3!D60)<3,"",GEOMEAN(Эксперт1!D60,Эксперт2!D60,Эксперт3!D60)) -> 1 | E60: =IF(COUNT(Эксперт1!E60,Эксперт2!E60,Эксперт3!E60)<3,"",GEOMEAN(Эксперт1!E60,Эксперт2!E60,Эксперт3!E60)) -> 4.3088694 | F60: =IF(COUNT(B60:E60)<4,"",GEOMEAN(B60:E60)) -> 2.8380653 | G60: =IFERROR(F60/SUM($F$58:$F$61),"") -> 0.56707033 | H60: =IFERROR(B60*$G$58+C60*$G$59+D60*$G$60+E60*$G$61,"") -> 2.2929024 | I60: =IFERROR(H60/G60,"") -> 4.043418
A61: =Справочник!$B$13 -> Привычки | B61: =IF(COUNT(Эксперт1!B61,Эксперт2!B61,Эксперт3!B61)<3,"",GEOMEAN(Эксперт1!B61,Эксперт2!B61,Эксперт3!B61)) -> 0.5 | C61: =IF(COUNT(Эксперт1!C61,Эксперт2!C61,Эксперт3!C61)<3,"",GEOMEAN(Эксперт1!C61,Эксперт2!C61,Эксперт3!C61)) -> 0.62996052 | D61: =IF(COUNT(Эксперт1!D61,Эксперт2!D61,Эксперт3!D61)<3,"",GEOMEAN(Эксперт1!D61,Эксперт2!D61,Эксперт3!D61)) -> 0.23207944 | E61: =IF(COUNT(Эксперт1!E61,Эксперт2!E61,Эксперт3!E61)<3,"",GEOMEAN(Эксперт1!E61,Эксперт2!E61,Эксперт3!E61)) -> 1 | F61: =IF(COUNT(B61:E61)<4,"",GEOMEAN(B61:E61)) -> 0.51997205 | G61: =IFERROR(F61/SUM($F$58:$F$61),"") -> 0.10389497 | H61: =IFERROR(B61*$G$58+C61*$G$59+D61*$G$60+E61*$G$61,"") -> 0.42094344 | I61: =IFERROR(H61/G61,"") -> 4.0516247
A62: lambda max | B62: =IF(COUNT(I58:I61)<4,"",AVERAGE(I58:I61)) -> 4.0343031 | C62: CI | D62: =IFERROR((B62-4)/(4-1),"") -> 0.011434365 | E62: CR (RI=0.9) | F62: =IFERROR(D62/0.9,"") -> 0.01270485 | G62: =IF(F62="","заполните матрицу",IF(F62<=0.1,"согласовано","CR > 0,1: пересмотреть")) -> согласовано
A69: ="Альтернативы по критерию: "&Справочник!$B$21 -> Альтернативы по критерию: Интерес и экспертиза команды
B70: =Справочник!$B$10 -> Бронь | C70: =Справочник!$B$11 -> Бюджет | D70: =Справочник!$B$12 -> Запись | E70: =Справочник!$B$13 -> Привычки | F70: Среднее геом. строки | G70: Вес w | H70: (A*w)i | I70: (A*w)i / wi
...
